Workbook

Sheet Plan de Test
A1: Déroulement général
B2: Un membre de l'équipe enseignante démarre l'exécution du plan de test, il effectue les tests de convivialité et note les résultats dans son propre fichier excel
B3: Le test sans perturbation est ensuite démarré. Au bout d'une minute ou deux, le membre de l'équipe enseignante prend en photo les courbes affichées, en prenant soin d'avoir le numéro de l'équipe dans la photo.
B4: Le membre de l'équipe enseignante peut alors quitter
B5: L'équipe complète le test selon les directives ci-bas et sauve les données pour remplir l'onglet "Réponse à l'échelon"
B6: Lorsque prête pour le test de perturbation, l'équipe lève la main
B7: Un membre de l'équipe enseignante démarre le test, lorsque la perturbation est allumée, il prend les courbes affichées en photo, avec le numéro d'équipe et peut quitter
B8: L'équipe complète le test selon les directives ci-bas et sauve les données pour remplir l'onglet "Réponse perturbation"
B9: Lorsque prête pour le test de robutesse, l'équipe lève la main
B10: Un membre de l'équipe enseignante démarre le test, il laisse tomber le prototype de 5 cm et l'asservissement est démarré. L'évaluateur note dans son propre fichier excel les manipulations nécessaires pour démarrer l'asservissement.
B11: Après une minute de chauffage, l'évalutateur cogne sur la table. Il attend encore une minute avant de prendre les courbes en photo
B12: L'équipe complète le test selon les directives ci-bas et sauve les données pour remplir l'onglet "Robustesse"
B14: L'équipe complète le fichier excel selon les directives et les templates donnés
... B21: Les enseignants procèdent à l'attribution des notes en utilisant l'information dans le fichier excel, notamment l'onglet "sommaire"
A23: Convivialité
B24: Voir l'onglet convivialité
A26: Réponse à l'échelon
B27: Démarrer l'asservissement avec une consigne à la température pièce (entre 23 et 25)
B28: Attendre que la consigne soit atteinte
B29: Mettre la consigne à 30 C
B30: Démarrer l'asservissement
B31: Attendre que la température soit stabilisée à la consigne
B32: Attendre au moins 5 minutes de plus
B33: Mettre la consigne à 20 C
B34: Attendre que la température soit stabilisée à la consigne
B35: Attendre au moins 5 minutes de plus
B36: Mettre la consigne à 23 C
B37: Attendre que la température soit stabilisée à la consigne
B38: Attendre au moins 5 minutes de plus
... B48: On obtient ainsi sdt30, std23 et std20, (voir onglet "Reponse échelon") qui sont repris à l'onglet "sommaire"
A50: Réponse à perturbation
B51: Démarrer l'asservissement avec une consigne à la température pièce (entre 23 et 25)
B52: Attendre que la consigne soit atteinte
B53: Mettre la consigne à 27 C
B54: Attendre que la température soit stabilisée à la consigne
B55: Attendre au moins 5 minutes de plus
B56: Appliquer la pertubation
B57: Attendre que la température soit stabilisée
B58: Attendre au moins 5 minutes de plus
B60: Sauvegarder les données et remplir l'onglet "Réponse perturbation'
...

Sheet Réponse échelon
A1: Time | B1: Setpoint | C1: Commande PWM | D1: Temp1 | E1: Temp2 | F1: Temp3_estime | G1: Temp3 | H1: T4 | I1: T3_moyen | J1: Erreur
A2: 573.5 | B2: 23.2 | C2: 129 | D2: 23.07 | E2: 23 | F2: 23.16 | G2: 23.03 | J2: 0.04
A3: =A2+0.5 -> 574 | B3: 23.2 | C3: 129 | D3: 23.09 | E3: 23 | F3: 23.16 | G3: 22.99 | J3: 0.04
A4: =A3+0.5 -> 574.5 | B4: 23.2 | C4: 129 | D4: 23.11 | E4: 23.06 | F4: 23.16 | G4: 23.05 | J4: 0.04 | L4: ecart30 | M4: {=MAX(ABS(I850:I1210-30))} -> 0.456 | O4: vous devez chosir la plage qui correspond aux 3 minutes centraux pendant laquelle la température est stabilités à 30C
A5: =A4+0.5 -> 575 | B5: 23.2 | C5: 129 | D5: 23.13 | E5: 23.06 | F5: 23.16 | G5: 23.07 | J5: 0.04 | L5: ecart23 | M5: {=MAX(ABS(I3582:I3942-23))} -> 0.1545 | O5: vous devez chosir la plage qui correspond aux 3 minutes centraux pendant laquelle la température est stabilités à 23C
A6: =A5+0.5 -> 575.5 | B6: 23.2 | C6: 129 | D6: 23.09 | E6: 23.04 | F6: 23.16 | G6: 23.07 | J6: 0.04 | L6: ecart20 | M6: {=MAX(ABS(I2337:I2697-20))} -> 0.116 | O6: vous devez chosir la plage qui correspond aux 3 minutes centraux pendant laquelle la température est stabilités à 20C
A7: =A6+0.5 -> 576 | B7: 23.2 | C7: 129 | D7: 23.09 | E7: 23.04 | F7: 23.16 | G7: 23.05 | J7: 0.04
A8: =A7+0.5 -> 576.5 | B8: 23.2 | C8: 129 | D8: 23.05 | E8: 22.95 | F8: 23.16 | G8: 23.07 | J8: 0.04 | L8: std30 | M8: =STDEV(I850:I1210) -> 0.031410747 | O8: vous devez chosir la plage qui correspond aux 3 minutes centraux pendant laquelle la température est stabilités à 30C
A9: =A8+0.5 -> 577 | B9: 23.2 | C9: 129 | D9: 23.05 | E9: 22.95 | F9: 23.15 | G9: 23.05 | J9: 0.04 | L9: std23 | M9: =STDEV(I3582:I3942) -> 0.009891466 | O9: vous devez chosir la plage qui correspond aux 3 minutes centraux pendant laquelle la température est stabilités à 23C
A10: =A9+0.5 -> 577.5 | B10: 23.2 | C10: 129 | D10: 23.13 | E10: 23.06 | F10: 23.15 | G10: 23.07 | J10: 0.04 | L10: std20 | M10: =STDEV(I2337:I2697) -> 0.03793666 | O10: vous devez chosir la plage qui correspond aux 3 minutes centraux pendant laquelle la température est stabilités à 20C
A11: =A10+0.5 -> 578 | B11: 23.2 | C11: 129 | D11: 23.09 | E11: 23.04 | F11: 23.15 | G11: 23.07 | J11: 0.04
A12: =A11+0.5 -> 578.5 | B12: 23.2 | C12: 129 | D12: 23.03 | E12: 23.06 | F12: 23.15 | G12: 23.05 | J12: 0.04
A13: =A12+0.5 -> 579 | B13: 23.2 | C13: 130 | D13: 23.07 | E13: 23 | F13: 23.15 | G13: 22.99 | J13: 0.05
A14: =A13+0.5 -> 579.5 | B14: 23.2 | C14: 130 | D14: 23.11 | E14: 23.04 | F14: 23.15 | G14: 23.07 | J14: 0.05 | L14: Temp min | M14: =MIN(I2137:I2497) -> 19.791 | O14: vous devez chosir la plage qui correspond aux 3 minutes centraux pendant laquelle la température est stabilités à 20C
A15: =A14+0.5 -> 580 | B15: 23.2 | C15: 130 | D15: 23.11 | E15: 23.04 | F15: 23.15 | G15: 23.03 | J15: 0.05 | L15: Temp max | M15: =MAX(I850:I1210) -> 29.67 | O15: vous devez chosir la plage qui correspond aux 3 minutes centraux pendant laquelle la température est stabilités à 30C
A16: =A15+0.5 -> 580.5 | B16: 23.2 | C16: 130 | D16: 23.13 | E16: 23.08 | F16: 23.15 | G16: 23.09 | J16: 0.05
A17: =A16+0.5 -> 581 | B17: 23.2 | C17: 130 | D17: 23.09 | E17: 23.02 | F17: 23.15 | G17: 23.01 | J17: 0.05
A18: =A17+0.5 -> 581.5 | B18: 23.2 | C18: 130 | D18: 23.09 | E18: 23 | F18: 23.15 | G18: 22.99 | J18: 0.05 | L18: Vous devez vous assurer que T3 moyenné est calculé correctement comme une moyenne glissante sur 20 secondes
A19: =A18+0.5 -> 582 | B19: 23.2 | C19: 130 | D19: 23.03 | E19: 22.97 | F19: 23.15 | G19: 23.07 | J19: 0.05
A20: =A19+0.5 -> 582.5 | B20: 23.2 | C20: 130 | D20: 23.09 | E20: 23.08 | F20: 23.15 | G20: 23.07 | J20: 0.05
A21: =A20+0.5 -> 583 | B21: 23.2 | C21: 130 | D21: 23.11 | E21: 23.04 | F21: 23.15 | G21: 23.05 | J21: 0.05 | L21: Les données fournies en exemple ne sont pas représentatives du test que vous allez faire !
A22: =A21+0.5 -> 583.5 | B22: 23.2 | C22: 130 | D22: 23.13 | E22: 23.06 | F22: 23.15 | G22: 23.05 | I22: =AVERAGE(G2:G41) -> 23.054 | J22: 0.05
A23: =A22+0.5 -> 584 | B23: 23.2 | C23: 130 | D23: 23.15 | E23: 23.06 | F23: 23.15 | G23: 23.09 | I23: =AVERAGE(G3:G42) -> 23.057 | J23: 0.05 | L23: Elle ne sont présentes que pour donner une idée de ce qui est attendu
A24: =A23+0.5 -> 584.5 | B24: 23.2 | C24: 130 | D24: 23.17 | E24: 23.08 | F24: 23.15 | G24: 23.07 | I24: =AVERAGE(G4:G43) -> 23.0595 | J24: 0.05
A25: =A24+0.5 -> 585 | B25: 23.2 | C25: 130 | D25: 23.11 | E25: 23.04 | F25: 23.15 | G25: 23.05 | I25: =AVERAGE(G5:G44) -> 23.061 | J25: 0.05
A26: =A25+0.5 -> 585.5 | B26: 23.2 | C26: 130 | D26: 23.13 | E26: 23.04 | F26: 23.15 | G26: 23.03 | I26: =AVERAGE(G6:G45) -> 23.0605 | J26: 0.05 | L26: Prenez soin d'indiquer avec un code de couleur, comme dans cet exemple quelles plages sont utilisées pour les calculs
A27: =A26+0.5 -> 586 | B27: 23.2 | C27: 130 | D27: 23.13 | E27: 23.04 | F27: 23.15 | G27: 23.07 | I27: =AVERAGE(G7:G46) -> 23.0615 | J27: 0.05
A28: =A27+0.5 -> 586.5 | B28: 23.2 | C28: 130 | D28: 23.13 | E28: 23.06 | F28: 23.15 | G28: 23.07 | I28: =AVERAGE(G8:G47) -> 23.0635 | J28: 0.05
A29: =A28+0.5 -> 587 | B29: 23.2 | C29: 130 | D29: 23.11 | E29: 23.02 | F29: 23.15 | G29: 23.05 | I29: =AVERAGE(G9:G48) -> 23.065 | J29: 0.05
A30: =A29+0.5 -> 587.5 | B30: 23.2 | C30: 130 | D30: 23.15 | E30: 23.04 | F30: 23.15 | G30: 23.01 | I30: =AVERAGE(G10:G49) -> 23.0675 | J30: 0.05
A31: =A30+0.5 -> 588 | B31: 23.2 | C31: 130 | D31: 23.15 | E31: 23.04 | F31: 23.15 | G31: 23.05 | I31: =AVERAGE(G11:G50) -> 23.0685 | J31: 0.05
A32: =A31+0.5 -> 588.5 | B32: 23.2 | C32: 130 | D32: 23.13 | E32: 23.06 | F32: 23.15 | G32: 23.07 | I32: =AVERAGE(G12:G51) -> 23.0695 | J32: 0.05
A33: =A32+0.5 -> 589 | B33: 23.2 | C33: 130 | D33: 23.15 | E33: 23.04 | F33: 23.15 | G33: 23.05 | I33: =AVERAGE(G13:G52) -> 23.071 | J33: 0.05
A34: =A33+0.5 -> 589.5 | B34: 23.2 | C34: 130 | D34: 23.15 | E34: 23.06 | F34: 23.15 | G34: 23.07 | I34: =AVERAGE(G14:G53) -> 23.074 | J34: 0.05
A35: =A34+0.5 -> 590 | B35: 23.2 | C35: 130 | D35: 23.13 | E35: 23.02 | F35: 23.15 | G35: 23.01 | I35: =AVERAGE(G15:G54) -> 23.0735 | J35: 0.05
A36: =A35+0.5 -> 590.5 | B36: 23.2 | C36: 130 | D36: 23.13 | E36: 23 | F36: 23.15 | G36: 23.01 | I36: =AVERAGE(G16:G55) -> 23.076 | J36: 0.05
A37: =A36+0.5 -> 591 | B37: 23.2 | C37: 130 | D37: 23.17 | E37: 23.06 | F37: 23.15 | G37: 23.05 | I37: =AVERAGE(G17:G56) -> 23.077 | J37: 0.05
A38: =A37+0.5 -> 591.5 | B38: 23.2 | C38: 130 | D38: 23.09 | E38: 23.06 | F38: 23.15 | G38: 23.07 | I38: =AVERAGE(G18:G57) -> 23.0795 | J38: 0.05
... A3942: =A3941+0.5 -> 2543.5 | B3942: 23 | C3942: 129 | D3942: 22.82 | E3942: 22.77 | F3942: 22.98 | G3942: 22.78 | I3942: =AVERAGE(G3922:G3961) -> 22.8525 | J3942: 0.01
A3943: =A3942+0.5 -> 2544 | B3943: 23 | C3943: 129 | D3943: 22.86 | E3943: 22.81 | F3943: 22.98 | G3943: 22.82 | J3943: 0.01
...

Sheet Réponse perturbation
A1: Time | B1: Setpoint | C1: Commande PWM | D1: Temp1 | E1: Temp2 | F1: Temp3_estime | G1: Temp3 | I1: T3 moyen
A2: 288.5 | B2: 23.2 | C2: 131 | D2: 23.21 | E2: 23.04 | F2: 23.17 | G2: 23.03
A3: =A2+0.5 -> 289 | B3: 23.2 | C3: 131 | D3: 23.15 | E3: 23 | F3: 23.17 | G3: 23.01
A4: =A3+0.5 -> 289.5 | B4: 23.2 | C4: 131 | D4: 23.19 | E4: 23.04 | F4: 23.17 | G4: 23.03 | K4: ecart27 | L4: {=MAX(ABS(I763:I1123-27))} -> 0.28560976 | N4: vous devez chosir la plage qui correspond aux 3 minutes centraux pendant laquelle la température est stabilités à 30C
A5: =A4+0.5 -> 290 | B5: 23.2 | C5: 131 | D5: 23.17 | E5: 23.04 | F5: 23.17 | G5: 23.03 | K5: ecart_pertu | L5: {=MAX(ABS(I2737:I3037-27))} -> 0.1495122 | N5: vous devez chosir la plage qui correspond aux 3 minutes centraux pendant laquelle la température est stabilités à 23C
A6: =A5+0.5 -> 290.5 | B6: 23.2 | C6: 131 | D6: 23.17 | E6: 23.06 | F6: 23.17 | G6: 23.03
A7: =A6+0.5 -> 291 | B7: 23.2 | C7: 131 | D7: 23.17 | E7: 23.06 | F7: 23.17 | G7: 23.03
A8: =A7+0.5 -> 291.5 | B8: 23.2 | C8: 131 | D8: 23.17 | E8: 23.06 | F8: 23.17 | G8: 23.03 | K8: std27 | L8: =STDEV(I763:I1123) -> 0.027807718 | N8: vous devez chosir la plage qui correspond aux 3 minutes centraux pendant laquelle la température est stabilités à 30C
A9: =A8+0.5 -> 292 | B9: 23.2 | C9: 131 | D9: 23.17 | E9: 23.06 | F9: 23.17 | G9: 23.05 | K9: std_pertu | L9: =STDEV(I2737:I3037) -> 0.016827022 | N9: vous devez chosir la plage qui correspond aux 3 minutes centraux pendant laquelle la température est stabilités à 23C
A10: =A9+0.5 -> 292.5 | B10: 23.2 | C10: 131 | D10: 23.17 | E10: 23.04 | F10: 23.17 | G10: 23.03
A11: =A10+0.5 -> 293 | B11: 23.2 | C11: 131 | D11: 23.15 | E11: 23 | F11: 23.17 | G11: 22.99
A12: =A11+0.5 -> 293.5 | B12: 23.2 | C12: 131 | D12: 23.17 | E12: 23.04 | F12: 23.17 | G12: 23.03
A13: =A12+0.5 -> 294 | B13: 23.2 | C13: 131 | D13: 23.17 | E13: 23.04 | F13: 23.17 | G13: 23.03 | K13: Vous devez vous assurer que T3 moyenné est calculé correctement comme une moyenne glissante sur 20 secondes
A14: =A13+0.5 -> 294.5 | B14: 23.2 | C14: 131 | D14: 23.15 | E14: 23.02 | F14: 23.17 | G14: 22.99
A15: =A14+0.5 -> 295 | B15: 23.2 | C15: 131 | D15: 23.15 | E15: 23.04 | F15: 23.17 | G15: 23.01
A16: =A15+0.5 -> 295.5 | B16: 23.2 | C16: 131 | D16: 23.13 | E16: 23.04 | F16: 23.17 | G16: 23.01 | K16: Les données fournies en exemple ne sont pas représentatives du test que vous allez faire !
A17: =A16+0.5 -> 296 | B17: 23.2 | C17: 131 | D17: 23.15 | E17: 23.04 | F17: 23.17 | G17: 23.03
A18: =A17+0.5 -> 296.5 | B18: 23.2 | C18: 131 | D18: 23.11 | E18: 23 | F18: 23.17 | G18: 23.05 | K18: Elle ne sont présentes que pour donner une idée de ce qui est attendu
A19: =A18+0.5 -> 297 | B19: 23.2 | C19: 131 | D19: 23.15 | E19: 23.04 | F19: 23.17 | G19: 23.03
A20: =A19+0.5 -> 297.5 | B20: 23.2 | C20: 131 | D20: 23.15 | E20: 23.04 | F20: 23.17 | G20: 23.01
A21: =A20+0.5 -> 298 | B21: 23.2 | C21: 131 | D21: 23.17 | E21: 23.06 | F21: 23.17 | G21: 23.03
A22: =A21+0.5 -> 298.5 | B22: 23.2 | C22: 131 | D22: 23.15 | E22: 23.04 | F22: 23.17 | G22: 23.03 | I22: =AVERAGE(G2:G42) -> 23.020732 | K22: Prenez soin d'indiquer avec un code de couleur, comme dans cet exemple quelles plages sont utilisées pour les calculs
A23: =A22+0.5 -> 299 | B23: 23.2 | C23: 131 | D23: 23.13 | E23: 23.02 | F23: 23.17 | G23: 22.99 | I23: =AVERAGE(G3:G43) -> 23.020732
A24: =A23+0.5 -> 299.5 | B24: 23.2 | C24: 131 | D24: 23.13 | E24: 23.04 | F24: 23.17 | G24: 23.03 | I24: =AVERAGE(G4:G44) -> 23.02122
A25: =A24+0.5 -> 300 | B25: 23.2 | C25: 131 | D25: 23.15 | E25: 23.04 | F25: 23.17 | G25: 23.03 | I25: =AVERAGE(G5:G45) -> 23.026098
A26: =A25+0.5 -> 300.5 | B26: 23.2 | C26: 131 | D26: 23.15 | E26: 23.04 | F26: 23.17 | G26: 23.01 | I26: =AVERAGE(G6:G46) -> 23.030976
A27: =A26+0.5 -> 301 | B27: 23.2 | C27: 131 | D27: 23.19 | E27: 23.06 | F27: 23.17 | G27: 23.01 | I27: =AVERAGE(G7:G47) -> 23.035854
A28: =A27+0.5 -> 301.5 | B28: 23.2 | C28: 131 | D28: 23.17 | E28: 23.06 | F28: 23.17 | G28: 23.03 | I28: =AVERAGE(G8:G48) -> 23.040732
A29: =A28+0.5 -> 302 | B29: 23.2 | C29: 131 | D29: 23.17 | E29: 23.04 | F29: 23.17 | G29: 23.03 | I29: =AVERAGE(G9:G49) -> 23.04561
A30: =A29+0.5 -> 302.5 | B30: 23.2 | C30: 131 | D30: 23.17 | E30: 23.06 | F30: 23.17 | G30: 23.03 | I30: =AVERAGE(G10:G50) -> 23.049512
A31: =A30+0.5 -> 303 | B31: 23.2 | C31: 131 | D31: 23.15 | E31: 23.04 | F31: 23.17 | G31: 23.03 | I31: =AVERAGE(G11:G51) -> 23.05439
A32: =A31+0.5 -> 303.5 | B32: 23.2 | C32: 131 | D32: 23.13 | E32: 23.02 | F32: 23.17 | G32: 23.05 | I32: =AVERAGE(G12:G52) -> 23.059268
A33: =A32+0.5 -> 304 | B33: 23.2 | C33: 131 | D33: 23.15 | E33: 23.04 | F33: 23.17 | G33: 23.03 | I33: =AVERAGE(G13:G53) -> 23.064146
A34: =A33+0.5 -> 304.5 | B34: 23.2 | C34: 131 | D34: 23.17 | E34: 23.04 | F34: 23.17 | G34: 22.99 | I34: =AVERAGE(G14:G54) -> 23.069512
... A3297: =A3296+0.5 -> 1936 | B3297: 27 | C3297: 145 | D3297: 28.1 | E3297: 27.42 | F3297: 26.97 | G3297: 26.85 | I3297: =AVERAGE(G3277:G3317) -> 26.855714

Sheet Robustesse
A1: Time | B1: Setpoint | C1: Commande PWM | D1: Temp1 | E1: Temp2 | F1: Temp3_est | G1: Temp3 | I1: T3 moyen
A2: 91.5 | B2: 23.2 | C2: 110 | D2: 23.01 | E2: 23.94 | F2: 23.65 | G2: 24.04
A3: =A2+0.5 -> 92 | B3: 23.2 | C3: 110 | D3: 22.99 | E3: 23.92 | F3: 23.65 | G3: 24.02
A4: =A3+0.5 -> 92.5 | B4: 23.2 | C4: 110 | D4: 22.99 | E4: 23.94 | F4: 23.65 | G4: 24.04 | K4: ecart28_robu | L4: {=MAX(ABS(I1061:I1421-28))} -> 0.04725 | N4: vous devez chosir la plage qui correspond aux 3 minutes centraux pendant laquelle la température est stabilités à 30C
A5: =A4+0.5 -> 93 | B5: 23.2 | C5: 110 | D5: 22.95 | E5: 23.88 | F5: 23.65 | G5: 24.04
A6: =A5+0.5 -> 93.5 | B6: 23.2 | C6: 110 | D6: 22.99 | E6: 23.92 | F6: 23.64 | G6: 24.02
A7: =A6+0.5 -> 94 | B7: 23.2 | C7: 110 | D7: 22.97 | E7: 23.94 | F7: 23.64 | G7: 24.04
A8: =A7+0.5 -> 94.5 | B8: 23.2 | C8: 110 | D8: 22.95 | E8: 23.9 | F8: 23.64 | G8: 24.02 | K8: sdt28_robu | L8: =STDEV(I1061:I1421) -> 0.016601755 | N8: vous devez chosir la plage qui correspond aux 3 minutes centraux pendant laquelle la température est stabilités à 30C
A9: =A8+0.5 -> 95 | B9: 23.2 | C9: 110 | D9: 22.95 | E9: 23.9 | F9: 23.63 | G9: 24
A10: =A9+0.5 -> 95.5 | B10: 23.2 | C10: 110 | D10: 22.97 | E10: 23.92 | F10: 23.63 | G10: 24.04
A11: =A10+0.5 -> 96 | B11: 23.2 | C11: 110 | D11: 22.97 | E11: 23.92 | F11: 23.63 | G11: 24.02
A12: =A11+0.5 -> 96.5 | B12: 23.2 | C12: 110 | D12: 22.92 | E12: 23.86 | F12: 23.62 | G12: 23.96
A13: =A12+0.5 -> 97 | B13: 23.2 | C13: 110 | D13: 22.92 | E13: 23.86 | F13: 23.62 | G13: 24.02 | K13: Vous devez vous assurer que T3 moyenné est calculé correctement comme une moyenne glissante sur 20 secondes
A14: =A13+0.5 -> 97.5 | B14: 23.2 | C14: 110 | D14: 22.95 | E14: 23.88 | F14: 23.62 | G14: 24
A15: =A14+0.5 -> 98 | B15: 23.2 | C15: 110 | D15: 22.9 | E15: 23.84 | F15: 23.61 | G15: 23.93
A16: =A15+0.5 -> 98.5 | B16: 23.2 | C16: 110 | D16: 22.95 | E16: 23.88 | F16: 23.61 | G16: 23.98 | K16: Les données fournies en exemple ne sont pas représentatives du test que vous allez faire !
A17: =A16+0.5 -> 99 | B17: 23.2 | C17: 110 | D17: 22.92 | E17: 23.88 | F17: 23.61 | G17: 24
A18: =A17+0.5 -> 99.5 | B18: 23.2 | C18: 110 | D18: 22.95 | E18: 23.88 | F18: 23.61 | G18: 24 | K18: Elle ne sont présentes que pour donner une idée de ce qui est attendu
A19: =A18+0.5 -> 100 | B19: 23.2 | C19: 110 | D19: 22.95 | E19: 23.88 | F19: 23.6 | G19: 24
A20: =A19+0.5 -> 100.5 | B20: 23.2 | C20: 110 | D20: 22.92 | E20: 23.86 | F20: 23.6 | G20: 23.98
A21: =A20+0.5 -> 101 | B21: 23.2 | C21: 110 | D21: 22.9 | E21: 23.86 | F21: 23.6 | G21: 23.98
A22: =A21+0.5 -> 101.5 | B22: 23.2 | C22: 111 | D22: 22.9 | E22: 23.86 | F22: 23.59 | G22: 23.98 | I22: =AVERAGE(F2:F41) -> 23.5945 | K22: Prenez soin d'indiquer avec un code de couleur, comme dans cet exemple, quelles plages sont utilisées pour les calculs
A23: =A22+0.5 -> 102 | B23: 23.2 | C23: 111 | D23: 22.86 | E23: 23.8 | F23: 23.59 | G23: 23.98 | I23: =AVERAGE(F3:F42) -> 23.5915
A24: =A23+0.5 -> 102.5 | B24: 23.2 | C24: 111 | D24: 22.88 | E24: 23.8 | F24: 23.59 | G24: 23.89 | I24: =AVERAGE(F4:F43) -> 23.5885
A25: =A24+0.5 -> 103 | B25: 23.2 | C25: 111 | D25: 22.88 | E25: 23.82 | F25: 23.58 | G25: 23.89 | I25: =AVERAGE(F5:F44) -> 23.5855
A26: =A25+0.5 -> 103.5 | B26: 23.2 | C26: 111 | D26: 22.9 | E26: 23.84 | F26: 23.58 | G26: 23.93 | I26: =AVERAGE(F6:F45) -> 23.5825
A27: =A26+0.5 -> 104 | B27: 23.2 | C27: 111 | D27: 22.88 | E27: 23.84 | F27: 23.58 | G27: 23.93 | I27: =AVERAGE(F7:F46) -> 23.5795
A28: =A27+0.5 -> 104.5 | B28: 23.2 | C28: 111 | D28: 22.86 | E28: 23.8 | F28: 23.57 | G28: 23.87 | I28: =AVERAGE(F8:F47) -> 23.5765
A29: =A28+0.5 -> 105 | B29: 23.2 | C29: 111 | D29: 22.88 | E29: 23.84 | F29: 23.57 | G29: 23.91 | I29: =AVERAGE(F9:F48) -> 23.5735
A30: =A29+0.5 -> 105.5 | B30: 23.2 | C30: 111 | D30: 22.86 | E30: 23.78 | F30: 23.57 | G30: 23.87 | I30: =AVERAGE(F10:F49) -> 23.5705
A31: =A30+0.5 -> 106 | B31: 23.2 | C31: 111 | D31: 22.84 | E31: 23.84 | F31: 23.56 | G31: 23.91 | I31: =AVERAGE(F11:F50) -> 23.5675
A32: =A31+0.5 -> 106.5 | B32: 23.2 | C32: 111 | D32: 22.9 | E32: 23.82 | F32: 23.56 | G32: 23.91 | I32: =AVERAGE(F12:F51) -> 23.5645
A33: =A32+0.5 -> 107 | B33: 23.2 | C33: 111 | D33: 22.88 | E33: 23.82 | F33: 23.56 | G33: 23.89 | I33: =AVERAGE(F13:F52) -> 23.56175
A34: =A33+0.5 -> 107.5 | B34: 23.2 | C34: 111 | D34: 22.88 | E34: 23.82 | F34: 23.56 | G34: 23.89 | I34: =AVERAGE(F14:F53) -> 23.55875
... A1536: =A1535+0.5 -> 858.5 | B1536: 28 | C1536: 153 | D1536: 29.47 | E1536: 28.42 | F1536: 27.94 | G1536: 27.7 | I1536: =AVERAGE(F1516:F1555) -> 27.944762

Sheet Convialité
A1: Convivialité | B1: indicateur | K1: pondération | L1: note
A3: Présence d'interface graphique | B3: 0 | K3: 1 | L3: =K3*B3 -> 0
A4: Possibilité de démarrer / arrêter l'asservissement | B4: 0 | K4: 1 | L4: =K4*B4 -> 0
A5: Possibilié de changer la consigne | B5: 0 | K5: 1 | L5: =K5*B5 -> 0
A6: Possibilité de modifier le régulateur | B6: 0 | K6: 1 | L6: =K6*B6 -> 0
A7: Voyant d'affichage de stabilité | B7: 0 | K7: 1 | L7: =K7*B7 -> 0
A8: Affichage des températures mesurées en temps réel | B8: 0 | C8: Un champ de texte == 1, Une courbe qui se met à jour == 2 | K8: 1 | L8: =K8*B8 -> 0
A9: Affichage de la température estimée / prédite en temps réel | B9: 0 | C9: Un champ de texte == 1, Une courbe qui se met à jour == 2 | K9: 1 | L9: =K9*B9 -> 0
A10: Affichage de la commande en temps réel | B10: 0 | C10: Un champ de texte == 1, Une courbe qui se met à jour == 2 | K10: 1 | L10: =K10*B10 -> 0
K12: Total convivialité: | L12: =SUM(L3:L10) -> 0
K13: Note convivialité | L13: =L12/20*100 -> 0
A15: Tous les éléments sont notés: | B15: 0 | C15: Absent
B16: 1 | C16: Minimalement présent
B17: 2 | C17: présent
A21: La pondération de chaque élément ne sera pas nécessairement la même dans la note

Sheet Courbes
AB6: 23.2-30 | AC6: 250
AB7: 30-20 | AC7: 400
AB8: 20-23 | AC8: 150
AB9: 23-27 | AC9: 200
AB10: pertub | AC10: 250
AB11: 23-28 | AC11: 175
AB16: Average | AC16: =AVERAGE(AC6,AC9,AC10:AC11) -> 218.75
N36: Prenez soin d'ajuster les plages des axes pour une lisibilité optimale des courbes
N41: Les évaluateurs vont utiliser ces courbes pour valider que les mesures correspondent à leurs photos
N46: Les évaluateurs vont utiliser ces courbes pour estimer les temps de réponses
N51: Prenez soin d'indiquer les régions utilisées pour les calculs avec le même code de couleur que dans les autres onglets

Sheet Sommaire
A1: Respect du cahier de charges
B3: spec | C3: valeur atteinte
A4: Température minimale | B4: 20 | C4: ='Réponse échelon'!M14 -> 19.791
A5: Température maximale | B5: 30 | C5: ='Réponse échelon'!M15 -> 29.67
A6: Précision en température | B6: 0.8 | C6: ='Réponse échelon'!M6 -> 0.116 | D6: ecart_20
B7: 0.8 | C7: ='Réponse échelon'!M5 -> 0.1545 | D7: ecart_23
B8: 0.8 | C8: ='Réponse perturbation'!L4 -> 0.28560976 | D8: ecart_27
B9: 0.8 | C9: ='Réponse perturbation'!L5 -> 0.1495122 | D9: ecart_27_perturbation
B10: 0.8 | C10: =Robustesse!L4 -> 0.04725 | D10: ecart_28_robustesse
B11: 0.8 | C11: ='Réponse échelon'!M4 -> 0.456 | D11: ecart_30
A13: Stabilité en température | B13: 0.1 | C13: ='Réponse échelon'!M10 -> 0.03793666 | D13: std_20
B14: 0.1 | C14: ='Réponse échelon'!M9 -> 0.009891466 | D14: std_23
B15: 0.1 | C15: ='Réponse perturbation'!L8 -> 0.027807718 | D15: std_27
B16: 0.1 | C16: ='Réponse perturbation'!L9 -> 0.016827022 | D16: std_27_perturbation
B17: 0.1 | C17: =Robustesse!L8 -> 0.016601755 | D17: std_28_robustesse
B18: 0.1 | C18: ='Réponse échelon'!M8 -> 0.031410747 | D18: std_30
A21: Robustesse | B21: 0 | C21: 0 | D21: Nombre de manipulations pour rendre le montage fonctionnel
A23: Convivialité | B23: 0.75 | C23: =Convialité!L13 -> 0 | D23: Voir la note dans l'onglet convivialité
A25: Temps de réponse | B25: 300 secondes | C25: 218 | D25: Évalateur: Prendre la moyenne du temps de stabilisation observé sur les courbes, enlever le pire et le meilleur résultat
A27: Voyant d'asservissement | B27: oui/non | C27: =Convialité!B7 -> 0
