Workbook

Sheet Plan de Test
A1: Déroulement général
B2: Un membre de l'équipe enseignante démarre l'exécution du plan de test, il effectue les tests de convivialité et note les résultats dans son propre fichier excel
B3: Le test sans perturbation est ensuite démarré. Au bout d'une minute ou deux, le membre de l'équipe enseignante prend en photo les courbes affichées, en prenant soin d'avoir le numéro de l'équipe dans la photo.
B4: Le membre de l'équipe enseignante peut alors quitter
B5: L'équipe complète le test selon les directives ci-bas et sauve les données pour remplir l'onglet "Réponse à l'échelon"
B6: Lorsque prête pour le test de perturbation, l'équipe lève la main
B7: Un membre de l'équipe enseignante démarre le test, lorsque la perturbation est allumée, il prend les courbes affichées en photo, avec le numéro d'équipe et peut quitter
B8: L'équipe complète le test selon les directives ci-bas et sauve les données pour remplir l'onglet "Réponse perturbation"
B9: Lorsque prête pour le test de robutesse, l'équipe lève la main
B10: Un membre de l'équipe enseignante démarre le test, il laisse tomber le prototype de 5 cm et l'asservissement est démarré. L'évaluateur note dans son propre fichier excel les manipulations nécessaires pour démarrer l'asservissement.
B11: Après une minute de chauffage, l'évalutateur cogne sur la table. Il attend encore une minute avant de prendre les courbes en photo
B12: L'équipe complète le test selon les directives ci-bas et sauve les données pour remplir l'onglet "Robustesse"
B14: L'équipe complète le fichier excel selon les directives et les templates donnés
... B21: Les enseignants procèdent à l'attribution des notes en utilisant l'information dans le fichier excel, notamment l'onglet "sommaire"
A23: Convivialité
B24: Voir l'onglet convivialité
A26: Réponse à l'échelon
B27: Démarrer l'asservissement avec une consigne à la température pièce (entre 23 et 25)
B28: Attendre que la consigne soit atteinte
B29: Mettre la consigne à 30 C
B30: Démarrer l'asservissement
B31: Attendre que la température soit stabilisée à la consigne
B32: Attendre au moins 5 minutes de plus
B33: Mettre la consigne à 20 C
B34: Attendre que la température soit stabilisée à la consigne
B35: Attendre au moins 5 minutes de plus
B36: Mettre la consigne à 23 C
B37: Attendre que la température soit stabilisée à la consigne
B38: Attendre au moins 5 minutes de plus
... B48: On obtient ainsi sdt30, std23 et std20, (voir onglet "Reponse échelon") qui sont repris à l'onglet "sommaire"
A50: Réponse à perturbation
B51: Démarrer l'asservissement avec une consigne à la température pièce (entre 23 et 25)
B52: Attendre que la consigne soit atteinte
B53: Mettre la consigne à 27 C
B54: Attendre que la température soit stabilisée à la consigne
B55: Attendre au moins 5 minutes de plus
B56: Appliquer la pertubation
B57: Attendre que la température soit stabilisée
B58: Attendre au moins 5 minutes de plus
B60: Sauvegarder les données et remplir l'onglet "Réponse perturbation'
...

Sheet Réponse échelon
A1: Temps | B1: (Consigne) | C1: U | D1: T1 | E1: T2 | F1: T3 | G1: T3 estimé | H1: (Erreur) | I1: (Stabilité) | J1: T3 moyen
A2: 359.5 | B2: 25 | C2: 132 | D2: 25.18 | E2: 25.26 | F2: 24.91 | G2: 25.1 | H2: -0.1 | I2: 1
A3: =A2+0.5 -> 360 | B3: 25 | C3: 132 | D3: 25.24 | E3: 25.32 | F3: 24.97 | G3: 25.1 | H3: -0.1 | I3: 1
A4: =A3+0.5 -> 360.5 | B4: 25 | C4: 132 | D4: 25.26 | E4: 25.34 | F4: 24.99 | G4: 25.1 | H4: -0.1 | I4: 1 | M4: ecart30 | N4: {=MAX(ABS(J541:J901-30))} -> 0.23 | P4: vous devez chosir la plage qui correspond aux 3 minutes centraux pendant laquelle la température est stabilités à 30C
A5: =A4+0.5 -> 361 | B5: 25 | C5: 132 | D5: 25.18 | E5: 25.24 | F5: 24.89 | G5: 25.1 | H5: -0.1 | I5: 1 | M5: ecart23 | N5: {=MAX(ABS(J3011:J3334-23))} -> 0.05 | P5: vous devez chosir la plage qui correspond aux 3 minutes centraux pendant laquelle la température est stabilités à 23C
A6: =A5+0.5 -> 361.5 | B6: 25 | C6: 132 | D6: 25.26 | E6: 25.37 | F6: 24.99 | G6: 25.1 | H6: -0.1 | I6: 1 | M6: ecart20 | N6: {=MAX(ABS(J2075:J2435-20))} -> 0.1 | P6: vous devez chosir la plage qui correspond aux 3 minutes centraux pendant laquelle la température est stabilités à 20C
A7: =A6+0.5 -> 362 | B7: 25 | C7: 132 | D7: 25.18 | E7: 25.28 | F7: 24.91 | G7: 25.1 | H7: -0.1 | I7: 1
A8: =A7+0.5 -> 362.5 | B8: 25 | C8: 132 | D8: 25.26 | E8: 25.37 | F8: 24.99 | G8: 25.1 | H8: -0.1 | I8: 1 | M8: std30 | N8: =STDEV(J541:J901) -> 0.028195744 | P8: vous devez chosir la plage qui correspond aux 3 minutes centraux pendant laquelle la température est stabilités à 30C
A9: =A8+0.5 -> 363 | B9: 25 | C9: 132 | D9: 25.24 | E9: 25.34 | F9: 24.99 | G9: 25.1 | H9: -0.1 | I9: 1 | M9: std23 | N9: =STDEV(J3011:J3334) -> 0.022275714 | P9: vous devez chosir la plage qui correspond aux 3 minutes centraux pendant laquelle la température est stabilités à 23C
A10: =A9+0.5 -> 363.5 | B10: 25 | C10: 132 | D10: 25.18 | E10: 25.26 | F10: 24.91 | G10: 25.1 | H10: -0.1 | I10: 1 | M10: std20 | N10: =STDEV(J2075:J2435) -> 0.039363374 | P10: vous devez chosir la plage qui correspond aux 3 minutes centraux pendant laquelle la température est stabilités à 20C
A11: =A10+0.5 -> 364 | B11: 25 | C11: 132 | D11: 25.22 | E11: 25.34 | F11: 24.99 | G11: 25.1 | H11: -0.1 | I11: 1
A12: =A11+0.5 -> 364.5 | B12: 25 | C12: 132 | D12: 25.22 | E12: 25.3 | F12: 24.93 | G12: 25.1 | H12: -0.1 | I12: 1
A13: =A12+0.5 -> 365 | B13: 25 | C13: 132 | D13: 25.24 | E13: 25.34 | F13: 24.99 | G13: 25.1 | H13: -0.1 | I13: 1
A14: =A13+0.5 -> 365.5 | B14: 25 | C14: 132 | D14: 25.22 | E14: 25.32 | F14: 24.97 | G14: 25.1 | H14: -0.1 | I14: 1 | M14: Temp min | N14: =MIN(J2075:J2435) -> 19.94 | P14: vous devez chosir la plage qui correspond aux 3 minutes centraux pendant laquelle la température est stabilités à 20C
A15: =A14+0.5 -> 366 | B15: 25 | C15: 132 | D15: 25.12 | E15: 25.28 | F15: 24.91 | G15: 25.1 | H15: -0.1 | I15: 1 | M15: Temp max | N15: =MAX(J541:J901) -> 29.87 | P15: vous devez chosir la plage qui correspond aux 3 minutes centraux pendant laquelle la température est stabilités à 30C
A16: =A15+0.5 -> 366.5 | B16: 25 | C16: 132 | D16: 25.24 | E16: 25.3 | F16: 24.93 | G16: 25.1 | H16: -0.1 | I16: 1
A17: =A16+0.5 -> 367 | B17: 25 | C17: 132 | D17: 25.24 | E17: 25.37 | F17: 25.01 | G17: 25.1 | H17: -0.1 | I17: 1
A18: =A17+0.5 -> 367.5 | B18: 25 | C18: 132 | D18: 25.18 | E18: 25.28 | F18: 24.93 | G18: 25.1 | H18: -0.1 | I18: 1
A19: =A18+0.5 -> 368 | B19: 25 | C19: 132 | D19: 25.22 | E19: 25.3 | F19: 24.93 | G19: 25.1 | H19: -0.1 | I19: 1 | M19: Temps de réponse selon voyant (s)
A20: =A19+0.5 -> 368.5 | B20: 25 | C20: 132 | D20: 25.18 | E20: 25.28 | F20: 24.93 | G20: 25.1 | H20: -0.1 | I20: 1
A21: =A20+0.5 -> 369 | B21: 25 | C21: 132 | D21: 25.22 | E21: 25.32 | F21: 24.97 | G21: 25.1 | H21: -0.1 | I21: 1 | M21: AMB_30 | N21: =A421-A33 -> 194
A22: =A21+0.5 -> 369.5 | B22: 25 | C22: 132 | D22: 25.18 | E22: 25.28 | F22: 24.91 | G22: 25.1 | H22: -0.1 | I22: 1 | J22: =ROUND(AVERAGE(F2:F42),2) -> 25.01 | M22: 30_20 | N22: =A1955-A1087 -> 434
A23: =A22+0.5 -> 370 | B23: 25 | C23: 132 | D23: 25.18 | E23: 25.28 | F23: 24.93 | G23: 25.1 | H23: -0.1 | I23: 1 | J23: =ROUND(AVERAGE(F3:F43),2) -> 25.03 | M23: 20_23 | N23: =A2891-A2620 -> 135.5
A24: =A23+0.5 -> 370.5 | B24: 25 | C24: 132 | D24: 25.24 | E24: 25.34 | F24: 24.99 | G24: 25.1 | H24: -0.1 | I24: 1 | J24: =ROUND(AVERAGE(F4:F44),2) -> 25.03
A25: =A24+0.5 -> 371 | B25: 25 | C25: 132 | D25: 25.24 | E25: 25.34 | F25: 24.99 | G25: 25.1 | H25: -0.1 | I25: 1 | J25: =ROUND(AVERAGE(F5:F45),2) -> 25.04
A26: =A25+0.5 -> 371.5 | B26: 25 | C26: 132 | D26: 25.22 | E26: 25.32 | F26: 24.99 | G26: 25.1 | H26: -0.1 | I26: 1 | J26: =ROUND(AVERAGE(F6:F46),2) -> 25.05
A27: =A26+0.5 -> 372 | B27: 25 | C27: 132 | D27: 25.2 | E27: 25.34 | F27: 24.97 | G27: 25.1 | H27: -0.1 | I27: 1 | J27: =ROUND(AVERAGE(F7:F47),2) -> 25.06
A28: =A27+0.5 -> 372.5 | B28: 25 | C28: 132 | D28: 25.16 | E28: 25.26 | F28: 24.91 | G28: 25.1 | H28: -0.1 | I28: 1 | J28: =ROUND(AVERAGE(F8:F48),2) -> 25.08
A29: =A28+0.5 -> 373 | B29: 25 | C29: 132 | D29: 25.22 | E29: 25.34 | F29: 24.99 | G29: 25.1 | H29: -0.1 | I29: 1 | J29: =ROUND(AVERAGE(F9:F49),2) -> 25.08
A30: =A29+0.5 -> 373.5 | B30: 25 | C30: 132 | D30: 25.22 | E30: 25.34 | F30: 24.99 | G30: 25.1 | H30: -0.1 | I30: 1 | J30: =ROUND(AVERAGE(F10:F50),2) -> 25.09
A31: =A30+0.5 -> 374 | B31: 25 | C31: 132 | D31: 25.16 | E31: 25.28 | F31: 24.91 | G31: 25.1 | H31: -0.1 | I31: 1 | J31: =ROUND(AVERAGE(F11:F51),2) -> 25.11
A32: =A31+0.5 -> 374.5 | B32: 25 | C32: 132 | D32: 25.24 | E32: 25.34 | F32: 24.99 | G32: 25.1 | H32: -0.1 | I32: 1 | J32: =ROUND(AVERAGE(F12:F52),2) -> 25.11
A33: =A32+0.5 -> 375 | B33: 30 | C33: 132 | D33: 25.18 | E33: 25.28 | F33: 24.93 | G33: 25.1 | H33: -0.1 | I33: 1 | J33: =ROUND(AVERAGE(F13:F53),2) -> 25.13 | K33: Changement consigne | L33: T
A34: =A33+0.5 -> 375.5 | B34: 30 | C34: 132 | D34: 25.24 | E34: 25.34 | F34: 24.99 | G34: 25.1 | H34: -0.1 | I34: 0 | J34: =ROUND(AVERAGE(F14:F54),2) -> 25.14 | M34: Vous devez vous assurer que T3 moyenné est calculé correctement comme une moyenne glissante sur 20 secondes
A35: =A34+0.5 -> 376 | B35: 30 | C35: 132 | D35: 25.22 | E35: 25.34 | F35: 24.99 | G35: 25.1 | H35: -0.1 | I35: 0 | J35: =ROUND(AVERAGE(F15:F55),2) -> 25.15
A36: =A35+0.5 -> 376.5 | B36: 30 | C36: 229 | D36: 25.18 | E36: 25.26 | F36: 24.95 | G36: 25.1 | H36: 4.9 | I36: 0 | J36: =ROUND(AVERAGE(F16:F56),2) -> 25.16
A37: =A36+0.5 -> 377 | B37: 30 | C37: 229 | D37: 25.57 | E37: 25.64 | F37: 25.34 | G37: 25.1 | H37: 4.9 | I37: 0 | J37: =ROUND(AVERAGE(F17:F57),2) -> 25.17 | K37: Transitoire | M37: Les données fournies en exemple ne sont pas représentatives du test que vous allez faire !
A38: =A37+0.5 -> 377.5 | B38: 30 | C38: 229 | D38: 25.68 | E38: 25.74 | F38: 25.39 | G38: 25.11 | H38: 4.9 | I38: 0 | J38: =ROUND(AVERAGE(F18:F58),2) -> 25.18
A39: =A38+0.5 -> 378 | B39: 30 | C39: 229 | D39: 25.7 | E39: 25.66 | F39: 25.32 | G39: 25.11 | H39: 4.9 | I39: 0 | J39: =ROUND(AVERAGE(F19:F59),2) -> 25.19 | M39: Elle ne sont présentes que pour donner une idée de ce qui est attendu
A40: =A39+0.5 -> 378.5 | B40: 30 | C40: 230 | D40: 25.89 | E40: 25.72 | F40: 25.37 | G40: 25.12 | H40: 4.89 | I40: 0 | J40: =ROUND(AVERAGE(F20:F60),2) -> 25.2
...

Sheet Réponse perturbation
A1: Temps | B1: (Consigne) | C1: U | D1: T1 | E1: T2 | F1: T3 | G1: T3 estimé | H1: (Erreur) | I1: (Stabilité) | J1: T3 moyen
A2: 39 | B2: 24 | C2: 127 | D2: 22.95 | E2: 23.15 | F2: 22.99 | G2: 23.31 | H2: 0 | I2: 0
A3: =A2+0.5 -> 39.5 | B3: 24 | C3: 127 | D3: 22.99 | E3: 23.25 | F3: 23.05 | G3: 23.31 | H3: 0 | I3: 0
A4: =A3+0.5 -> 40 | B4: 24 | C4: 127 | D4: 23.05 | E4: 23.23 | F4: 23.05 | G4: 23.31 | H4: 0 | I4: 0 | L4: ecart27 | M4: {=MAX(ABS(J734:J1094-27))} -> 0.1 | O4: vous devez chosir la plage qui correspond aux 3 minutes centraux pendant laquelle la température est stabilités à 30C
A5: =A4+0.5 -> 40.5 | B5: 24 | C5: 127 | D5: 22.97 | E5: 23.15 | F5: 22.99 | G5: 23.31 | H5: 0 | I5: 0 | L5: ecart_pertu | M5: {=MAX(ABS(J1847:J2207-27))} -> 0.37 | O5: vous devez chosir la plage qui correspond aux 3 minutes centraux pendant laquelle la température est stabilités à 23C
A6: =A5+0.5 -> 41 | B6: 24 | C6: 127 | D6: 23.07 | E6: 23.23 | F6: 23.03 | G6: 23.31 | H6: 0 | I6: 0
A7: =A6+0.5 -> 41.5 | B7: 24 | C7: 127 | D7: 22.97 | E7: 23.15 | F7: 22.95 | G7: 23.31 | H7: 0 | I7: 0
A8: =A7+0.5 -> 42 | B8: 24 | C8: 127 | D8: 23.05 | E8: 23.27 | F8: 23.03 | G8: 23.3 | H8: 0 | I8: 0 | L8: std27 | M8: =STDEV(J734:J1094) -> 0.024003757 | O8: vous devez chosir la plage qui correspond aux 3 minutes centraux pendant laquelle la température est stabilités à 30C
A9: =A8+0.5 -> 42.5 | B9: 24 | C9: 127 | D9: 23.07 | E9: 23.25 | F9: 23.03 | G9: 23.3 | H9: 0 | I9: 0 | L9: std_pertu | M9: =STDEV(J1847:J2207) -> 0.076767718 | O9: vous devez chosir la plage qui correspond aux 3 minutes centraux pendant laquelle la température est stabilités à 23C
A10: =A9+0.5 -> 43 | B10: 24 | C10: 127 | D10: 22.97 | E10: 23.15 | F10: 22.95 | G10: 23.31 | H10: 0 | I10: 0
A11: =A10+0.5 -> 43.5 | B11: 24 | C11: 127 | D11: 23.05 | E11: 23.23 | F11: 23.03 | G11: 23.3 | H11: 0 | I11: 0
A12: =A11+0.5 -> 44 | B12: 24 | C12: 127 | D12: 23.03 | E12: 23.21 | F12: 23.01 | G12: 23.3 | H12: 0 | I12: 0 | L12: Temps de réponse selon voyant (s)
A13: =A12+0.5 -> 44.5 | B13: 24 | C13: 127 | D13: 23.11 | E13: 23.3 | F13: 23.09 | G13: 23.3 | H13: 0 | I13: 0
A14: =A13+0.5 -> 45 | B14: 24 | C14: 127 | D14: 23.09 | E14: 23.3 | F14: 23.07 | G14: 23.3 | H14: 0 | I14: 0 | L14: AMB_27 | M14: =A614-A390 -> 112
A15: =A14+0.5 -> 45.5 | B15: 24 | C15: 127 | D15: 22.99 | E15: 23.17 | F15: 22.97 | G15: 23.31 | H15: 0 | I15: 0 | L15: 27_perturb | M15: =A1727-A1274 -> 226.5
A16: =A15+0.5 -> 46 | B16: 24 | C16: 127 | D16: 23.13 | E16: 23.32 | F16: 23.09 | G16: 23.3 | H16: 0 | I16: 0
A17: =A16+0.5 -> 46.5 | B17: 24 | C17: 127 | D17: 23.13 | E17: 23.32 | F17: 23.11 | G17: 23.31 | H17: 0 | I17: 0
A18: =A17+0.5 -> 47 | B18: 24 | C18: 127 | D18: 23.13 | E18: 23.34 | F18: 23.11 | G18: 23.31 | H18: 0 | I18: 0
A19: =A18+0.5 -> 47.5 | B19: 24 | C19: 127 | D19: 23.13 | E19: 23.34 | F19: 23.11 | G19: 23.31 | H19: 0 | I19: 0
A20: =A19+0.5 -> 48 | B20: 24 | C20: 127 | D20: 23.07 | E20: 23.25 | F20: 23.03 | G20: 23.31 | H20: 0 | I20: 0
A21: =A20+0.5 -> 48.5 | B21: 24 | C21: 127 | D21: 23.13 | E21: 23.32 | F21: 23.09 | G21: 23.31 | H21: 0 | I21: 0
A22: =A21+0.5 -> 49 | B22: 24 | C22: 127 | D22: 23.15 | E22: 23.32 | F22: 23.09 | G22: 23.31 | H22: 0 | I22: 0 | J22: =ROUND(AVERAGE(F2:F42),2) -> 23.07
A23: =A22+0.5 -> 49.5 | B23: 24 | C23: 127 | D23: 23.07 | E23: 23.23 | F23: 23.03 | G23: 23.32 | H23: 0 | I23: 0 | J23: =ROUND(AVERAGE(F3:F43),2) -> 23.08
A24: =A23+0.5 -> 50 | B24: 24 | C24: 127 | D24: 23.13 | E24: 23.38 | F24: 23.13 | G24: 23.32 | H24: 0 | I24: 0 | J24: =ROUND(AVERAGE(F4:F44),2) -> 23.08
A25: =A24+0.5 -> 50.5 | B25: 24 | C25: 127 | D25: 23.13 | E25: 23.27 | F25: 23.05 | G25: 23.32 | H25: 0 | I25: 0 | J25: =ROUND(AVERAGE(F5:F45),2) -> 23.09
A26: =A25+0.5 -> 51 | B26: 24 | C26: 127 | D26: 23.19 | E26: 23.36 | F26: 23.13 | G26: 23.32 | H26: 0 | I26: 0 | J26: =ROUND(AVERAGE(F6:F46),2) -> 23.09
A27: =A26+0.5 -> 51.5 | B27: 24 | C27: 127 | D27: 23.19 | E27: 23.36 | F27: 23.13 | G27: 23.32 | H27: 0 | I27: 0 | J27: =ROUND(AVERAGE(F7:F47),2) -> 23.09
A28: =A27+0.5 -> 52 | B28: 24 | C28: 127 | D28: 23.11 | E28: 23.27 | F28: 23.03 | G28: 23.32 | H28: 0 | I28: 0 | J28: =ROUND(AVERAGE(F8:F48),2) -> 23.1
A29: =A28+0.5 -> 52.5 | B29: 24 | C29: 127 | D29: 23.19 | E29: 23.36 | F29: 23.11 | G29: 23.32 | H29: 0 | I29: 0 | J29: =ROUND(AVERAGE(F9:F49),2) -> 23.1
A30: =A29+0.5 -> 53 | B30: 24 | C30: 127 | D30: 23.13 | E30: 23.34 | F30: 23.15 | G30: 23.33 | H30: 0 | I30: 0 | J30: =ROUND(AVERAGE(F10:F50),2) -> 23.1
A31: =A30+0.5 -> 53.5 | B31: 24 | C31: 127 | D31: 23.21 | E31: 23.38 | F31: 23.13 | G31: 23.33 | H31: 0 | I31: 0 | J31: =ROUND(AVERAGE(F11:F51),2) -> 23.11
A32: =A31+0.5 -> 54 | B32: 24 | C32: 127 | D32: 23.19 | E32: 23.36 | F32: 23.13 | G32: 23.33 | H32: 0 | I32: 0 | J32: =ROUND(AVERAGE(F12:F52),2) -> 23.11
A33: =A32+0.5 -> 54.5 | B33: 24 | C33: 127 | D33: 23.13 | E33: 23.3 | F33: 23.03 | G33: 23.33 | H33: 0 | I33: 0 | J33: =ROUND(AVERAGE(F13:F53),2) -> 23.12
A34: =A33+0.5 -> 55 | B34: 24 | C34: 127 | D34: 23.21 | E34: 23.4 | F34: 23.13 | G34: 23.33 | H34: 0 | I34: 0 | J34: =ROUND(AVERAGE(F14:F54),2) -> 23.12 | L34: Vous devez vous assurer que T3 moyenné est calculé correctement comme une moyenne glissante sur 20 secondes
A35: =A34+0.5 -> 55.5 | B35: 24 | C35: 127 | D35: 23.19 | E35: 23.36 | F35: 23.09 | G35: 23.34 | H35: 0 | I35: 0 | J35: =ROUND(AVERAGE(F15:F55),2) -> 23.12
A36: =A35+0.5 -> 56 | B36: 24 | C36: 127 | D36: 23.15 | E36: 23.32 | F36: 23.07 | G36: 23.34 | H36: 0 | I36: 0 | J36: =ROUND(AVERAGE(F16:F56),2) -> 23.13
A37: =A36+0.5 -> 56.5 | B37: 24 | C37: 127 | D37: 23.23 | E37: 23.4 | F37: 23.17 | G37: 23.34 | H37: 0 | I37: 0 | J37: =ROUND(AVERAGE(F17:F57),2) -> 23.13 | L37: Les données fournies en exemple ne sont pas représentatives du test que vous allez faire !
A38: =A37+0.5 -> 57 | B38: 24 | C38: 127 | D38: 23.17 | E38: 23.32 | F38: 23.07 | G38: 23.34 | H38: 0 | I38: 0 | J38: =ROUND(AVERAGE(F18:F58),2) -> 23.14
A39: =A38+0.5 -> 57.5 | B39: 24 | C39: 127 | D39: 23.17 | E39: 23.44 | F39: 23.17 | G39: 23.34 | H39: 0 | I39: 0 | J39: =ROUND(AVERAGE(F19:F59),2) -> 23.14 | L39: Elle ne sont présentes que pour donner une idée de ce qui est attendu
A40: =A39+0.5 -> 58 | B40: 24 | C40: 127 | D40: 23.21 | E40: 23.44 | F40: 23.15 | G40: 23.34 | H40: 0 | I40: 0 | J40: =ROUND(AVERAGE(F20:F60),2) -> 23.14
...

Sheet Robustesse
A1: Temps | B1: (Consigne) | C1: U | D1: T1 | E1: T2 | F1: T3 | G1: T3 estimé | H1: (Erreur) | I1: (Stabilité) | J1: T3 moyen
A2: 25 | B2: 24 | C2: 127 | D2: 25.72 | E2: 26.18 | F2: 25.91 | G2: 25.3 | H2: 0 | I2: 0
A3: =A2+0.5 -> 25.5 | B3: 24 | C3: 127 | D3: 25.78 | E3: 26.24 | F3: 25.93 | G3: 25.31 | H3: 0 | I3: 0
A4: =A3+0.5 -> 26 | B4: 24 | C4: 127 | D4: 25.74 | E4: 26.2 | F4: 25.93 | G4: 25.32 | H4: 0 | I4: 0 | L4: ecart28_robu | M4: {=MAX(ABS(J737:J1097-28))} -> 0.09 | O4: vous devez chosir la plage qui correspond aux 3 minutes centraux pendant laquelle la température est stabilités à 30C
A5: =A4+0.5 -> 26.5 | B5: 24 | C5: 127 | D5: 25.8 | E5: 26.24 | F5: 25.95 | G5: 25.33 | H5: 0 | I5: 0
A6: =A5+0.5 -> 27 | B6: 24 | C6: 127 | D6: 25.78 | E6: 26.22 | F6: 25.91 | G6: 25.34 | H6: 0 | I6: 0
A7: =A6+0.5 -> 27.5 | B7: 24 | C7: 127 | D7: 25.66 | E7: 26.14 | F7: 25.91 | G7: 25.35 | H7: 0 | I7: 0
A8: =A7+0.5 -> 28 | B8: 24 | C8: 127 | D8: 25.78 | E8: 26.24 | F8: 25.95 | G8: 25.36 | H8: 0 | I8: 0 | L8: sdt28_robu | M8: =STDEV(J737:J1097) -> 0.0089440999 | O8: vous devez chosir la plage qui correspond aux 3 minutes centraux pendant laquelle la température est stabilités à 30C
A9: =A8+0.5 -> 28.5 | B9: 24 | C9: 127 | D9: 25.8 | E9: 26.22 | F9: 25.95 | G9: 25.36 | H9: 0 | I9: 0
A10: =A9+0.5 -> 29 | B10: 24 | C10: 127 | D10: 25.74 | E10: 26.18 | F10: 25.91 | G10: 25.37 | H10: 0 | I10: 0
A11: =A10+0.5 -> 29.5 | B11: 24 | C11: 127 | D11: 25.76 | E11: 26.2 | F11: 25.93 | G11: 25.38 | H11: 0 | I11: 0
A12: =A11+0.5 -> 30 | B12: 24 | C12: 127 | D12: 25.72 | E12: 26.16 | F12: 25.93 | G12: 25.39 | H12: 0 | I12: 0 | L12: Temps de réponse selon voyant (s)
A13: =A12+0.5 -> 30.5 | B13: 24 | C13: 127 | D13: 25.78 | E13: 26.22 | F13: 25.95 | G13: 25.39 | H13: 0 | I13: 0
A14: =A13+0.5 -> 31 | B14: 24 | C14: 127 | D14: 25.7 | E14: 26.14 | F14: 25.97 | G14: 25.4 | H14: 0 | I14: 0 | L14: AMB_28 | M14: =A617-A381 -> 118
A15: =A14+0.5 -> 31.5 | B15: 24 | C15: 127 | D15: 25.68 | E15: 26.16 | F15: 25.89 | G15: 25.41 | H15: 0 | I15: 0
A16: =A15+0.5 -> 32 | B16: 24 | C16: 127 | D16: 25.76 | E16: 26.2 | F16: 25.95 | G16: 25.41 | H16: 0 | I16: 0
A17: =A16+0.5 -> 32.5 | B17: 24 | C17: 127 | D17: 25.68 | E17: 26.14 | F17: 25.85 | G17: 25.42 | H17: 0 | I17: 0
A18: =A17+0.5 -> 33 | B18: 24 | C18: 127 | D18: 25.76 | E18: 26.2 | F18: 25.95 | G18: 25.43 | H18: 0 | I18: 0
A19: =A18+0.5 -> 33.5 | B19: 24 | C19: 127 | D19: 25.74 | E19: 26.22 | F19: 25.95 | G19: 25.43 | H19: 0 | I19: 0
A20: =A19+0.5 -> 34 | B20: 24 | C20: 127 | D20: 25.62 | E20: 26.14 | F20: 25.89 | G20: 25.44 | H20: 0 | I20: 0
A21: =A20+0.5 -> 34.5 | B21: 24 | C21: 127 | D21: 25.76 | E21: 26.18 | F21: 25.93 | G21: 25.44 | H21: 0 | I21: 0
A22: =A21+0.5 -> 35 | B22: 24 | C22: 127 | D22: 25.68 | E22: 26.12 | F22: 25.87 | G22: 25.45 | H22: 0 | I22: 0 | J22: =ROUND(AVERAGE(F2:F42),2) -> 25.89
A23: =A22+0.5 -> 35.5 | B23: 24 | C23: 127 | D23: 25.74 | E23: 26.18 | F23: 25.93 | G23: 25.45 | H23: 0 | I23: 0 | J23: =ROUND(AVERAGE(F3:F43),2) -> 25.89
A24: =A23+0.5 -> 36 | B24: 24 | C24: 127 | D24: 25.72 | E24: 26.18 | F24: 25.93 | G24: 25.46 | H24: 0 | I24: 0 | J24: =ROUND(AVERAGE(F4:F44),2) -> 25.88
A25: =A24+0.5 -> 36.5 | B25: 24 | C25: 127 | D25: 25.66 | E25: 26.1 | F25: 25.85 | G25: 25.46 | H25: 0 | I25: 0 | J25: =ROUND(AVERAGE(F5:F45),2) -> 25.88
A26: =A25+0.5 -> 37 | B26: 24 | C26: 127 | D26: 25.72 | E26: 26.16 | F26: 25.89 | G26: 25.47 | H26: 0 | I26: 0 | J26: =ROUND(AVERAGE(F6:F46),2) -> 25.88
A27: =A26+0.5 -> 37.5 | B27: 24 | C27: 127 | D27: 25.76 | E27: 26.16 | F27: 25.85 | G27: 25.47 | H27: 0 | I27: 0 | J27: =ROUND(AVERAGE(F7:F47),2) -> 25.87
A28: =A27+0.5 -> 38 | B28: 24 | C28: 127 | D28: 25.72 | E28: 26.14 | F28: 25.91 | G28: 25.48 | H28: 0 | I28: 0 | J28: =ROUND(AVERAGE(F8:F48),2) -> 25.87
A29: =A28+0.5 -> 38.5 | B29: 24 | C29: 127 | D29: 25.7 | E29: 26.14 | F29: 25.89 | G29: 25.48 | H29: 0 | I29: 0 | J29: =ROUND(AVERAGE(F9:F49),2) -> 25.87
A30: =A29+0.5 -> 39 | B30: 24 | C30: 127 | D30: 25.64 | E30: 26.08 | F30: 25.82 | G30: 25.48 | H30: 0 | I30: 0 | J30: =ROUND(AVERAGE(F10:F50),2) -> 25.86
A31: =A30+0.5 -> 39.5 | B31: 24 | C31: 127 | D31: 25.66 | E31: 26.12 | F31: 25.85 | G31: 25.49 | H31: 0 | I31: 0 | J31: =ROUND(AVERAGE(F11:F51),2) -> 25.86
A32: =A31+0.5 -> 40 | B32: 24 | C32: 127 | D32: 25.7 | E32: 26.14 | F32: 25.89 | G32: 25.49 | H32: 0 | I32: 0 | J32: =ROUND(AVERAGE(F12:F52),2) -> 25.86
A33: =A32+0.5 -> 40.5 | B33: 24 | C33: 127 | D33: 25.62 | E33: 26.03 | F33: 25.78 | G33: 25.49 | H33: 0 | I33: 0 | J33: =ROUND(AVERAGE(F13:F53),2) -> 25.85
A34: =A33+0.5 -> 41 | B34: 24 | C34: 127 | D34: 25.68 | E34: 26.14 | F34: 25.89 | G34: 25.5 | H34: 0 | I34: 0 | J34: =ROUND(AVERAGE(F14:F54),2) -> 25.85 | L34: Vous devez vous assurer que T3 moyenné est calculé correctement comme une moyenne glissante sur 20 secondes
A35: =A34+0.5 -> 41.5 | B35: 24 | C35: 127 | D35: 25.62 | E35: 26.05 | F35: 25.78 | G35: 25.5 | H35: 0 | I35: 0 | J35: =ROUND(AVERAGE(F15:F55),2) -> 25.84
A36: =A35+0.5 -> 42 | B36: 24 | C36: 127 | D36: 25.66 | E36: 26.1 | F36: 25.87 | G36: 25.5 | H36: 0 | I36: 0 | J36: =ROUND(AVERAGE(F16:F56),2) -> 25.84
A37: =A36+0.5 -> 42.5 | B37: 24 | C37: 127 | D37: 25.66 | E37: 26.1 | F37: 25.85 | G37: 25.5 | H37: 0 | I37: 0 | J37: =ROUND(AVERAGE(F17:F57),2) -> 25.84 | L37: Les données fournies en exemple ne sont pas représentatives du test que vous allez faire !
A38: =A37+0.5 -> 43 | B38: 24 | C38: 127 | D38: 25.59 | E38: 26.05 | F38: 25.8 | G38: 25.51 | H38: 0 | I38: 0 | J38: =ROUND(AVERAGE(F18:F58),2) -> 25.83
A39: =A38+0.5 -> 43.5 | B39: 24 | C39: 127 | D39: 25.68 | E39: 26.12 | F39: 25.85 | G39: 25.51 | H39: 0 | I39: 0 | J39: =ROUND(AVERAGE(F19:F59),2) -> 25.83 | L39: Elle ne sont présentes que pour donner une idée de ce qui est attendu
A40: =A39+0.5 -> 44 | B40: 24 | C40: 127 | D40: 25.59 | E40: 26.03 | F40: 25.76 | G40: 25.51 | H40: 0 | I40: 0 | J40: =ROUND(AVERAGE(F20:F60),2) -> 25.82
...

Sheet Convialité
A1: Convivialité | B1: indicateur | K1: pondération | L1: note
A3: Présence d'interface graphique | B3: 0 | K3: 1 | L3: =K3*B3 -> 0
A4: Possibilité de démarrer / arrêter l'asservissement | B4: 0 | K4: 1 | L4: =K4*B4 -> 0
A5: Possibilié de changer la consigne | B5: 0 | K5: 1 | L5: =K5*B5 -> 0
A6: Possibilité de modifier le régulateur | B6: 0 | K6: 1 | L6: =K6*B6 -> 0
A7: Voyant d'affichage de stabilité | B7: 0 | K7: 1 | L7: =K7*B7 -> 0
A8: Affichage des températures mesurées en temps réel | B8: 0 | C8: Un champ de texte == 1, Une courbe qui se met à jour == 2 | K8: 1 | L8: =K8*B8 -> 0
A9: Affichage de la température estimée / prédite en temps réel | B9: 0 | C9: Un champ de texte == 1, Une courbe qui se met à jour == 2 | K9: 1 | L9: =K9*B9 -> 0
A10: Affichage de la commande en temps réel | B10: 0 | C10: Un champ de texte == 1, Une courbe qui se met à jour == 2 | K10: 1 | L10: =K10*B10 -> 0
K12: Total convivialité: | L12: =SUM(L3:L10) -> 0
K13: Note convivialité | L13: =L12/20*100 -> 0
A15: Tous les éléments sont notés: | B15: 0 | C15: Absent
B16: 1 | C16: Minimalement présent
B17: 2 | C17: présent
A21: La pondération de chaque élément ne sera pas nécessairement la même dans la note

Sheet Courbes
N36: Prenez soin d'ajuster les plages des axes pour une lisibilité optimale des courbes
N41: Les évaluateurs vont utiliser ces courbes pour valider que les mesures correspondent à leurs photos
N46: Les évaluateurs vont utiliser ces courbes pour estimer les temps de réponses : !Déjà calculer grace au voyant de stabilité voir sommaire
N51: Prenez soin d'indiquer les régions utilisées pour les calculs avec le même code de couleur que dans les autres onglets

Sheet Sommaire
A1: Respect du cahier de charges
F2: * Tout nos plages de calculs sont basé sur le voyant de stabilité du protoype directement ( t+60 à t+240 )
B3: spec | C3: valeur atteinte | F3: * Nos temps de réponses aussi
A4: Température minimale | B4: 20 | C4: ='Réponse échelon'!N14 -> 19.94
A5: Température maximale | B5: 30 | C5: ='Réponse échelon'!N15 -> 29.87 | F5: Temp de réponse selon voyant stabilité:
A6: Précision en température | B6: 0.8 | C6: ='Réponse échelon'!N6 -> 0.1 | D6: ecart_20
C7: ='Réponse échelon'!N5 -> 0.05 | D7: ecart_23 | F7: ='Réponse échelon'!M21 -> AMB_30 | G7: ='Réponse échelon'!N21 -> 194 | H7: =G7 -> 194
C8: ='Réponse perturbation'!M4 -> 0.1 | D8: ecart_27 | F8: ='Réponse échelon'!M22 -> 30_20 | G8: ='Réponse échelon'!N22 -> 434 | I8: Enlever (pire)
C9: ='Réponse perturbation'!M5 -> 0.37 | D9: ecart_27_perturbation | F9: ='Réponse échelon'!M23 -> 20_23 | G9: ='Réponse échelon'!N23 -> 135.5 | H9: =G9 -> 135.5
C10: =Robustesse!M4 -> 0.09 | D10: ecart_28_robustesse | F10: ='Réponse perturbation'!L14 -> AMB_27 | G10: ='Réponse perturbation'!M14 -> 112 | I10: Enlever (meilleur)
C11: ='Réponse échelon'!N4 -> 0.23 | D11: ecart_30 | F11: ='Réponse perturbation'!L15 -> 27_perturb | G11: ='Réponse perturbation'!M15 -> 226.5 | H11: =G11 -> 226.5
F12: =Robustesse!L14 -> AMB_28 | G12: =Robustesse!M14 -> 118 | H12: =G12 -> 118
A13: Stabilité en température | B13: 0.1 | C13: ='Réponse échelon'!N10 -> 0.039363374 | D13: std_20
C14: ='Réponse échelon'!N9 -> 0.022275714 | D14: std_23 | F14: Moyenne | G14: =AVERAGE(G7:G12) -> 203.33333 | H14: sec
C15: ='Réponse perturbation'!M8 -> 0.024003757 | D15: std_27 | F15: Moyenne selon evaluation: | H15: =AVERAGE(H7:H12) -> 168.5 | I15: sec
C16: ='Réponse perturbation'!M9 -> 0.076767718 | D16: std_27_perturbation
C17: =Robustesse!M8 -> 0.0089440999 | D17: std_28_robustesse
C18: ='Réponse échelon'!N8 -> 0.028195744 | D18: std_30
A21: Robustesse | C21: 0 | D21: Nombre de manipulations pour rendre le montage fonctionnel
A23: Convivialité | B23: 0.75 | C23: =Convialité!L13 -> 0 | D23: Voir la note dans l'onglet convivialité
A25: Temps de réponse | B25: 300 secondes | C25: Équipe :**168.5sec*** | D25: Évalateur: Prendre la moyenne du temps de stabilisation observé sur les courbes, enlever le pire et le meilleur résultat
A27: Voyant d'asservissement | B27: oui/non | C27: =Convialité!B7 -> 0
